<sdf version='1.7'>
  <model name='turtlebot3_burger'>
    <link name='base_footprint'>
      <inertial>
        <pose>-0.000401 0 0.011936 0 -0 0</pose>
        <mass>10.119</mass>
        <inertia>
          <ixx>0.105335</ixx>
          <ixy>0</ixy>
          <ixz>0.00061799</ixz>
          <iyy>0.105483</iyy>
          <iyz>1.05879e-22</iyz>
          <izz>0.102148</izz>
        </inertia>
      </inertial>
      <collision name='base_footprint_fixed_joint_lump__base_link_collision'>
        <pose>-0.032 0 0.08 0 -0 0</pose>
        <geometry>
          <box>
            <size>4 1 0.1</size>
          </box>
        </geometry>
      </collision>
      <collision name='base_footprint_fixed_joint_lump__caster_back_link_collision_1'>
        <pose>-0.081 1e-06 0.005 -1.57 0 0</pose>
        <geometry>
          <box>
            <size>0.03 0.009 0.02</size>
          </box>
        </geometry>
      </collision>
      <collision name='base_footprint_fixed_joint_lump__base_scan_collision_2'>
        <pose>-0.017 0 0.1755 0 -0 0</pose>
        <geometry>
          <cylinder>
            <length>0.0315</length>
            <radius>0.055</radius>
          </cylinder>
        </geometry>
      </collision>
      <visual name='base_footprint_fixed_joint_lump__base_link_visual'>
        <pose>0 0 0.01 0 -0 0</pose>
        <geometry>
          <mesh>
            <scale>0.001 0.001 0.001</scale>
            <uri>model://turtlebot3_gazebo/models/turtlebot3_common/meshes/burger_base.dae</uri>
          </mesh>
        </geometry>
      </visual>
      <visual name='base_footprint_fixed_joint_lump__base_scan_visual_1'>
        <pose>-0.032 0 0.182 0 -0 0</pose>
        <geometry>
          <mesh>
            <scale>0.001 0.001 0.001</scale>
            <uri>model://turtlebot3_gazebo/models/turtlebot3_common/meshes/lds.dae</uri>
          </mesh>
        </geometry>
      </visual>
    </link>
    <joint name='wheel_left_joint' type='revolute'>
      <pose relative_to='base_footprint'>0 0.4 -0.04 1.5708 -0 3.14159</pose>
      <parent>base_footprint</parent>
      <child>wheel_left_link</child>
      <axis>
        <xyz>0 0 1</xyz>
        <limit>
          <lower>-1e+16</lower>
          <upper>1e+16</upper>
        </limit>
        <dynamics>
          <spring_reference>0</spring_reference>
          <spring_stiffness>0</spring_stiffness>
        </dynamics>
      </axis>
    </joint>
    <link name='wheel_left_link'>
      <pose relative_to='wheel_left_joint'>0 0 0 0 -0 0</pose>
      <inertial>
        <pose>0 0 0 0 -0 0</pose>
        <mass>1</mass>
        <inertia>
          <ixx>0.01</ixx>
          <ixy>0</ixy>
          <ixz>0</ixz>
          <iyy>0.01</iyy>
          <iyz>0</iyz>
          <izz>0.01</izz>
        </inertia>
      </inertial>
      <collision name='wheel_left_link_collision'>
        <pose>0 0 0 0 -0 0</pose>
        <geometry>
          <cylinder>
            <length>0.05</length>
            <radius>0.05</radius>
          </cylinder>
        </geometry>
      </collision>
      <visual name='wheel_left_link_visual'>
        <pose>0 0 0 1.57 -0 0</pose>
        <geometry>
          <cylinder>
            <length>0.05</length>
            <radius>0.05</radius>
          </cylinder>
        </geometry>
      </visual>
    </link>
    <joint name='wheel_right_joint' type='revolute'>
      <pose relative_to='base_footprint'>0 -0.4 -0.04 1.5708 -0 3.14159</pose>
      <parent>base_footprint</parent>
      <child>wheel_right_link</child>
      <axis>
        <xyz>0 0 1</xyz>
        <limit>
          <lower>-1e+16</lower>
          <upper>1e+16</upper>
        </limit>
        <dynamics>
          <spring_reference>0</spring_reference>
          <spring_stiffness>0</spring_stiffness>
        </dynamics>
      </axis>
    </joint>
    <link name='wheel_right_link'>
      <pose relative_to='wheel_right_joint'>0 0 0 0 -0 0</pose>
      <inertial>
        <pose>0 0 0 0 -0 0</pose>
        <mass>1</mass>
        <inertia>
          <ixx>0.01</ixx>
          <ixy>0</ixy>
          <ixz>0</ixz>
          <iyy>0.01</iyy>
          <iyz>0</iyz>
          <izz>0.01</izz>
        </inertia>
      </inertial>
      <collision name='wheel_right_link_collision'>
        <pose>0 0 0 0 -0 0</pose>
        <geometry>
          <cylinder>
            <length>0.05</length>
            <radius>0.05</radius>
          </cylinder>
        </geometry>
      </collision>
      <visual name='wheel_right_link_visual'>
        <pose>0 0 0 1.57 -0 0</pose>
        <geometry>
          <cylinder>
            <length>0.05</length>
            <radius>0.05</radius>
          </cylinder>
        </geometry>
      </visual>
    </link>
  </model>
</sdf>
